<?xml version="1.0"?>
<robot xmlns:xacro="http://www.ros.org/wiki/xacro" name="walker" >
  <link name="world"/>

	<link
    name="left_palm_link">
    <inertial>
      <origin
        xyz="0.0144809215118954 -0.0132347085538364 0.022306335464008"
        rpy="0 0 0" />
      <mass
        value="0.0852752510078387" />
      <inertia
        ixx="0.000154775131402232"
        ixy="1.85109602266807E-05"
        ixz="7.47252049170957E-06"
        iyy="0.000107981762301999"
        iyz="-1.08345230717271E-06"
        izz="0.000125562926987643" />
    </inertial>
    <visual>
      <origin
        xyz="0 0 0"
        rpy="0 0 0" />
      <geometry>
        <mesh
          filename="package://hand_description/meshes/left_palm_link.STL" />
      </geometry>
      <material
        name="">
        <color
          rgba="0.752941176470588 0.752941176470588 0.752941176470588 1" />
      </material>
    </visual>
    <collision>
      <origin
        xyz="0.020 -0.005 0.020"
        rpy="0 0 0" />
      <geometry>
        <box size="0.040 0.090 0.100"/>
      </geometry>
    </collision>
  </link>
	<gazebo reference="left_palm_link">
    <!-- <selfCollide>true</selfCollide>-->
    <material>Gazebo/White</material>
    <mu1>1000.0</mu1>
    <mu2>1000.0</mu2>
    <fdir1>0.0 0.0 1.0</fdir1>
    <kp>1e5</kp>
    <kd>1.0</kd>
  </gazebo>
  <joint
    name="left_palm_joint"
    type="fixed">
    <origin
      xyz="0.073849 0.0065547 0.01588"
      rpy="3.14159 0 -1.309" /><!--py="3.14159 0 -1.35"xyz="0.073849 -0.0065547 -0.01588"-->
    <parent
      link="world" />
    <child
      link="left_palm_link" />
    <axis
      xyz="0 0 0" />
  </joint>
	<gazebo reference="left_palm_joint">
    <implicitSpringDamper>true</implicitSpringDamper>
  </gazebo>
	<link
    name="left_thumb_l1">
    <inertial>
      <origin
        xyz="0.0109077935886571 0.000509912566104553 -0.00754109244201351"
        rpy="0 0 0" />
      <mass
        value="0.00861402024435377" />
      <inertia
        ixx="6.47370281406322E-07"
        ixy="-2.31312229115831E-08"
        ixz="-4.83971007188494E-09"
        iyy="1.90672646289156E-06"
        iyz="1.40014779445703E-09"
        izz="1.98821903169097E-06" />
    </inertial>
    <visual>
      <origin
        xyz="0 0 0"
        rpy="0 0 0" />
      <geometry>
        <mesh
          filename="package://hand_description/meshes/left_thumb_l1.STL" />
      </geometry>
      <material
        name="">
        <color
          rgba="0.752941176470588 0.752941176470588 0.752941176470588 1" />
      </material>
    </visual>
    <collision>
      <origin
        xyz="0.008 0.002 -0.008"
        rpy="0 1.5708 0" />
      <geometry>
        <cylinder length="0.028" radius="0.012"/>
      </geometry>
    </collision>
  </link>
	<gazebo reference="left_thumb_l1">
    <!-- <selfCollide>true</selfCollide>-->
  </gazebo>
	<joint
    name="left_thumb_j1"
    type="revolute">
    <origin
      xyz="-0.029569 -0.010189 0.047224"
      rpy="-0.21969 0.11307 -2.3458" />
    <parent
      link="left_palm_link" />
    <child
      link="left_thumb_l1" />
    <axis
      xyz="0 0 1" />
    <limit
      lower="0"
      upper="1.5708"
      effort="1.0"
      velocity="10" />
		<dynamics damping="0.01" friction="0.0"/>
  </joint>
	<gazebo reference="left_thumb_j1">
    <implicitSpringDamper>true</implicitSpringDamper>
  </gazebo>
	<link
    name="left_thumb_l2">
    <inertial>
      <origin
        xyz="-0.00326118817213394 -0.00670732804360867 0.00579509755504815"
        rpy="0 0 0" />
      <mass
        value="0.00424320273530089" />
      <inertia
        ixx="3.56339942071856E-07"
        ixy="-1.03305625527354E-07"
        ixz="-1.98675685150365E-08"
        iyy="2.76640278902837E-07"
        iyz="-2.89571665413786E-08"
        izz="4.20445500389883E-07" />
    </inertial>
    <visual>
      <origin
        xyz="0 0 0"
        rpy="0 0 0" />
      <geometry>
        <mesh
          filename="package://hand_description/meshes/left_thumb_l2.STL" />
      </geometry>
      <material
        name="">
        <color
          rgba="0.752941176470588 0.752941176470588 0.752941176470588 1" />
      </material>
    </visual>
    <collision>
      <origin
        xyz="-0.007 -0.009 0.007"
        rpy="0 1.5708 0.7854" />
      <geometry>
        <cylinder length="0.025" radius="0.012"/>
      </geometry>
    </collision>
  </link>
	<gazebo reference="left_thumb_l2">
    <!-- <selfCollide>true</selfCollide>-->
    <material>Gazebo/White</material>
    <mu1>1000.0</mu1>
    <mu2>1000.0</mu2>
    <fdir1>0.0 0.0 1.0</fdir1>
    <kp>1e5</kp>
    <kd>1.0</kd>
  </gazebo>
	<joint
    name="left_thumb_j2"
    type="revolute">
    <origin
      xyz="0.03655 0 -0.014552"
      rpy="-0.23401 -0.07871 2.3426" />
    <parent
      link="left_thumb_l1" />
    <child
      link="left_thumb_l2" />
    <axis
      xyz="0.078637 -0.23116 0.96973" />
    <limit
      lower="0"
      upper="1.5708"
      effort="1.0"
      velocity="10" />
		<dynamics damping="0.01" friction="0.0"/>
		<mimic joint="left_thumb_j1" multiplier="1.0" offset="0.0" />
  </joint>
	<gazebo reference="left_thumb_j2">
    <implicitSpringDamper>true</implicitSpringDamper>
  </gazebo>
	<link
    name="left_index_l1">
    <inertial>
      <origin
        xyz="0.0150096995375729 -0.000417441681978437 -0.00617410792227591"
        rpy="0 0 0" />
      <mass
        value="0.00596800864397499" />
      <inertia
        ixx="3.61715487571409E-07"
        ixy="1.11394201694589E-08"
        ixz="-9.49522570972701E-09"
        iyy="1.352263185051E-06"
        iyz="3.77704526134077E-10"
        izz="1.37239697071942E-06" />
    </inertial>
    <visual>
      <origin
        xyz="0 0 0"
        rpy="0 0 0" />
      <geometry>
        <mesh
          filename="package://hand_description/meshes/left_index_l1.STL" />
      </geometry>
      <material
        name="">
        <color
          rgba="0.752941176470588 0.752941176470588 0.752941176470588 1" />
      </material>
    </visual>
    <collision>
      <origin
        xyz="0.014 0 -0.005"
        rpy="0 1.5708 0" />
      <geometry>
        <cylinder length="0.034" radius="0.010"/>
      </geometry>
    </collision>
  </link>
	<gazebo reference="left_index_l1">
    <!-- <selfCollide>true</selfCollide>-->
  </gazebo>
	<joint
    name="left_index_j1"
    type="revolute">
    <origin
      xyz="0.019862 -0.070838 0.061199"
      rpy="0.007028 -0.014656 -1.7541" />
    <parent
      link="left_palm_link" />
    <child
      link="left_index_l1" />
    <axis
      xyz="0 0 -1" />
    <limit
      lower="0"
      upper="1.5708"
      effort="1.0"
      velocity="10" />
		<dynamics damping="0.01" friction="0.0"/>
  </joint>
	<gazebo reference="left_index_j1">
    <implicitSpringDamper>true</implicitSpringDamper>
  </gazebo>
	<link
    name="left_index_l2">
    <inertial>
      <origin
        xyz="-0.00253991682124299 -0.00977023427268975 0.00611226603304443"
        rpy="0 0 0" />
      <mass
        value="0.00445721097773791" />
      <inertia
        ixx="5.54377117420834E-07"
        ixy="-8.29083645268593E-08"
        ixz="1.27238638879939E-09"
        iyy="2.07584978771715E-07"
        iyz="6.4186623927502E-09"
        izz="5.97533598597632E-07" />
    </inertial>
    <visual>
      <origin
        xyz="0 0 0"
        rpy="0 0 0" />
      <geometry>
        <mesh
          filename="package://hand_description/meshes/left_index_l2.STL" />
      </geometry>
      <material
        name="">
        <color
          rgba="0.752941176470588 0.752941176470588 0.752941176470588 1" />
      </material>
    </visual>
    <collision>
      <origin
        xyz="-0.002 -0.014 0.007"
        rpy="1.5708 0 -0.1745" />
      <geometry>
        <cylinder length="0.032" radius="0.010"/>
      </geometry>
    </collision>
  </link>
	<gazebo reference="left_index_l2">
    <!-- <selfCollide>true</selfCollide>-->
    <material>Gazebo/White</material>
    <mu1>1000.0</mu1>
    <mu2>1000.0</mu2>
    <fdir1>0.0 0.0 1.0</fdir1>
    <kp>1e5</kp>
    <kd>1.0</kd>
  </gazebo>
	<joint
    name="left_index_j2"
    type="revolute">
    <origin
      xyz="0.038461 0 -0.012199"
      rpy="0.015691 0.0042391 1.7541" />
    <parent
      link="left_index_l1" />
    <child
      link="left_index_l2" />
    <axis
      xyz="-0.004239 0.015691 -0.99987" />
    <limit
      lower="0"
      upper="1.5708"
      effort="1.0"
      velocity="10" />
		<dynamics damping="0.01" friction="0.0"/>
    <mimic joint="left_index_j1" multiplier="1.0" offset="0.0" />
  </joint>
	<gazebo reference="left_index_j2">
    <implicitSpringDamper>true</implicitSpringDamper>
  </gazebo>
	<link
    name="left_middle_l1">
    <inertial>
      <origin
        xyz="0.0150066791389904 -0.000415057780457695 -0.00617388522006262"
        rpy="0 0 0" />
      <mass
        value="0.0059679127929483" />
      <inertia
        ixx="3.61683279235401E-07"
        ixy="1.10458760225662E-08"
        ixz="-9.52816793557932E-09"
        iyy="1.35225818715739E-06"
        iyz="4.31044880666154E-10"
        izz="1.37239159556213E-06" />
    </inertial>
    <visual>
      <origin
        xyz="0 0 0"
        rpy="0 0 0" />
      <geometry>
        <mesh
          filename="package://hand_description/meshes/left_middle_l1.STL" />
      </geometry>
      <material
        name="">
        <color
          rgba="0.752941176470588 0.752941176470588 0.752941176470588 1" />
      </material>
    </visual>
    <collision>
      <origin
        xyz="0.014 0 -0.005"
        rpy="0 1.5708 0" />
      <geometry>
        <cylinder length="0.034" radius="0.010"/>
      </geometry>
    </collision>
  </link>
	<gazebo reference="left_middle_l1">
    <!-- <selfCollide>true</selfCollide>-->
  </gazebo>
	<joint
    name="left_middle_j1"
    type="revolute">
    <origin
      xyz="0.021755 -0.077461 0.037447"
      rpy="0.0068833 -0.014869 -1.7395" />
    <parent
      link="left_palm_link" />
    <child
      link="left_middle_l1" />
    <axis
      xyz="0 0 -1" />
    <limit
      lower="0"
      upper="1.5708"
      effort="1.0"
      velocity="10" />
		<dynamics damping="0.01" friction="0.0"/>
  </joint>
	<gazebo reference="left_middle_j1">
    <implicitSpringDamper>true</implicitSpringDamper>
  </gazebo>
	<link
    name="left_middle_l2">
    <inertial>
      <origin
        xyz="-0.0022619297447487 -0.00982259010744915 0.00611526424902847"
        rpy="0 0 0" />
      <mass
        value="0.004457212283002" />
      <inertia
        ixx="5.58236463390729E-07"
        ixy="-7.2571176025331E-08"
        ixz="1.16573185460247E-09"
        iyy="1.98180605286849E-07"
        iyz="6.55275148489497E-09"
        izz="5.91969671305025E-07" />
    </inertial>
    <visual>
      <origin
        xyz="0 0 0"
        rpy="0 0 0" />
      <geometry>
        <mesh
          filename="package://hand_description/meshes/left_middle_l2.STL" />
      </geometry>
      <material
        name="">
        <color
          rgba="0.752941176470588 0.752941176470588 0.752941176470588 1" />
      </material>
    </visual>
    <collision>
      <origin
        xyz="-0.002 -0.014 0.007"
        rpy="1.5708 0 -0.1745" />
      <geometry>
        <cylinder length="0.032" radius="0.010"/>
      </geometry>
    </collision>
  </link>
	<gazebo reference="left_middle_l2">
    <!-- <selfCollide>true</selfCollide>-->
    <material>Gazebo/White</material>
    <mu1>1000.0</mu1>
    <mu2>1000.0</mu2>
    <fdir1>0.0 0.0 1.0</fdir1>
    <kp>1e5</kp>
    <kd>1.0</kd>
  </gazebo>
	<joint
    name="left_middle_j2"
    type="revolute">
    <origin
      xyz="0.038459 0 -0.0122"
      rpy="0.015814 0.0042886 1.7395" />
    <parent
      link="left_middle_l1" />
    <child
      link="left_middle_l2" />
    <axis
      xyz="-0.0042886 0.015813 -0.99987" />
    <limit
      lower="0"
      upper="1.5708"
      effort="1.0"
      velocity="10" />
		<dynamics damping="0.01" friction="0.0"/>
		<mimic joint="left_middle_j1" multiplier="1.0" offset="0.0" />
  </joint>
	<gazebo reference="left_middle_j2">
    <implicitSpringDamper>true</implicitSpringDamper>
  </gazebo>
	<link
    name="left_ring_l1">
    <inertial>
      <origin
        xyz="0.0150066465487988 -0.000417740690980883 -0.00617161773568659"
        rpy="0 0 0" />
      <mass
        value="0.00596757485212751" />
      <inertia
        ixx="3.6154970839031E-07"
        ixy="1.12995090649401E-08"
        ixz="-9.55073355700821E-09"
        iyy="1.35207882018888E-06"
        iyz="3.71727201013289E-10"
        izz="1.37236862180291E-06" />
    </inertial>
    <visual>
      <origin
        xyz="0 0 0"
        rpy="0 0 0" />
      <geometry>
        <mesh
          filename="package://hand_description/meshes/left_ring_l1.STL" />
      </geometry>
      <material
        name="">
        <color
          rgba="0.752941176470588 0.752941176470588 0.752941176470588 1" />
      </material>
    </visual>
    <collision>
      <origin
        xyz="0.014 0 -0.005"
        rpy="0 1.5708 0" />
      <geometry>
        <cylinder length="0.034" radius="0.010"/>
      </geometry>
    </collision>
  </link>
	<gazebo reference="left_ring_l1">
    <!-- <selfCollide>true</selfCollide>-->
  </gazebo>
	<joint
    name="left_ring_j1"
    type="revolute">
    <origin
      xyz="0.020863 -0.073224 0.013361"
      rpy="0.0058882 -0.015148 -1.6781" />
    <parent
      link="left_palm_link" />
    <child
      link="left_ring_l1" />
    <axis
      xyz="1.7588E-05 0 -1" />
    <limit
      lower="0"
      upper="1.5708"
      effort="1.0"
      velocity="10" />
		<dynamics damping="0.01" friction="0.0"/>
  </joint>
	<gazebo reference="left_ring_j1">
    <implicitSpringDamper>true</implicitSpringDamper>
  </gazebo>
	<link
    name="left_ring_l2">
    <inertial>
      <origin
        xyz="-0.00178574011082344 -0.0099345155093529 0.0061186229082168"
        rpy="0 0 0" />
      <mass
        value="0.00445721563393106" />
      <inertia
        ixx="5.6496205492444E-07"
        ixy="-5.57715446692935E-08"
        ixz="8.36286600459378E-10"
        iyy="1.9706692522115E-07"
        iyz="6.65676794938147E-09"
        izz="5.97527568635283E-07" />
    </inertial>
    <visual>
      <origin
        xyz="0 0 0"
        rpy="0 0 0" />
      <geometry>
        <mesh
          filename="package://hand_description/meshes/left_ring_l2.STL" />
      </geometry>
      <material
        name="">
        <color
          rgba="0.752941176470588 0.752941176470588 0.752941176470588 1" />
      </material>
    </visual>
    <collision>
      <origin
        xyz="-0.002 -0.014 0.007"
        rpy="1.5708 0 -0.1745" />
      <geometry>
        <cylinder length="0.032" radius="0.010"/>
      </geometry>
    </collision>
  </link>
	<gazebo reference="left_ring_l2">
    <!-- <selfCollide>true</selfCollide>-->
    <material>Gazebo/White</material>
    <mu1>1000.0</mu1>
    <mu2>1000.0</mu2>
    <fdir1>0.0 0.0 1.0</fdir1>
    <kp>1e5</kp>
    <kd>1.0</kd>
  </gazebo>
	<joint
    name="left_ring_j2"
    type="revolute">
    <origin
      xyz="0.038459 0 -0.012203"
      rpy="0.015691 0.0042325 1.6781" />
    <parent
      link="left_ring_l1" />
    <child
      link="left_ring_l2" />
    <axis
      xyz="-0.0042344 0.015673 -0.99987" />
    <limit
      lower="0"
      upper="1.5708"
      effort="1.0"
      velocity="10" />
		<dynamics damping="0.01" friction="0.0"/>
    <mimic joint="left_ring_j1" multiplier="1.0" offset="0.0" />
  </joint>
	<gazebo reference="left_ring_j2">
    <implicitSpringDamper>true</implicitSpringDamper>
  </gazebo>
	<link
    name="left_pinky_l1">
    <inertial>
      <origin
        xyz="0.0129948215470049 6.7441505780419E-05 -0.00569979807526588"
        rpy="0 0 0" />
      <mass
        value="0.00474006684614483" />
      <inertia
        ixx="2.40789497863744E-07"
        ixy="6.40265040823268E-09"
        ixz="2.07928316306501E-09"
        iyy="8.43737864578879E-07"
        iyz="7.44359550503124E-10"
        izz="8.5149387942E-07" />
    </inertial>
    <visual>
      <origin
        xyz="0 0 0"
        rpy="0 0 0" />
      <geometry>
        <mesh
          filename="package://hand_description/meshes/left_pinky_l1.STL" />
      </geometry>
      <material
        name="">
        <color
          rgba="0.752941176470588 0.752941176470588 0.752941176470588 1" />
      </material>
    </visual>
    <collision>
      <origin
        xyz="0.014 0 -0.005"
        rpy="0 1.5708 0" />
      <geometry>
        <cylinder length="0.034" radius="0.010"/>
      </geometry>
    </collision>
  </link>
	<gazebo reference="left_pinky_l1">
    <!-- <selfCollide>true</selfCollide>-->
  </gazebo>
	<joint
    name="left_pinky_j1"
    type="revolute">
    <origin
      xyz="0.021779 -0.069944 -0.010184"
      rpy="-0.034105 -0.016248 -1.6441" />
    <parent
      link="left_palm_link" />
    <child
      link="left_pinky_l1" />
    <axis
      xyz="6.6172E-05 0 -1" />
    <limit
      lower="0"
      upper="1.5708"
      effort="1.0"
      velocity="10" />
		<dynamics damping="0.01" friction="0.0"/>
		<mimic joint="left_ring_j1" multiplier="1.0" offset="0.0" />
  </joint>
	<gazebo reference="left_pinky_j1">
    <implicitSpringDamper>true</implicitSpringDamper>
  </gazebo>
	<link
    name="left_pinky_l2">
    <inertial>
      <origin
        xyz="-0.00207317179159261 -0.0122243534973791 -0.00503143611359247"
        rpy="0 0 0" />
      <mass
        value="0.00390644847680527" />
      <inertia
        ixx="5.18285631399026E-07"
        ixy="-5.55253133559814E-08"
        ixz="2.07796178117026E-09"
        iyy="1.49229602527441E-07"
        iyz="9.30943070175501E-09"
        izz="5.41041706459008E-07" />
    </inertial>
    <visual>
      <origin
        xyz="0 0 0"
        rpy="0 0 0" />
      <geometry>
        <mesh
          filename="package://hand_description/meshes/left_pinky_l2.STL" />
      </geometry>
      <material
        name="">
        <color
          rgba="0.752941176470588 0.752941176470588 0.752941176470588 1" />
      </material>
    </visual>
    <collision>
      <origin
        xyz="-0.004 -0.020 -0.005"
        rpy="1.5708 0 -0.1745" />
      <geometry>
        <cylinder length="0.032" radius="0.010"/>
      </geometry>
    </collision>
  </link>
	<gazebo reference="left_pinky_l2">
    <!-- <selfCollide>true</selfCollide>-->
    <material>Gazebo/White</material>
    <mu1>1000.0</mu1>
    <mu2>1000.0</mu2>
    <fdir1>0.0 0.0 1.0</fdir1>
    <kp>1e5</kp>
    <kd>1.0</kd>
  </gazebo>
	<joint
    name="left_pinky_j2"
    type="revolute">
    <origin
      xyz="0.03311 0.00034528 -0.00040579"
      rpy="0.013704 -0.035204 1.6442" />
    <parent
      link="left_pinky_l1" />
    <child
      link="left_pinky_l2" />
    <axis
      xyz="0.035197 0.013623 -0.99929" />
    <limit
      lower="0"
      upper="1.5708"
      effort="1.0"
      velocity="10" />
		<dynamics damping="0.01" friction="0.0"/>
    <mimic joint="left_ring_j1" multiplier="1.0" offset="0.0" />
  </joint>
	<gazebo reference="left_pinky_j2">
    <implicitSpringDamper>true</implicitSpringDamper>
  </gazebo>

	<xacro:mimic_joint_plugin_gazebo name_prefix="left_thumb_j2"
    parent_joint="left_thumb_j1" mimic_joint="left_thumb_j2" multiplier="1.0" offset="0.0" />
	<xacro:mimic_joint_plugin_gazebo name_prefix="left_index_j2"
    parent_joint="left_index_j1" mimic_joint="left_index_j2" multiplier="1.0" offset="0.0" />
	<xacro:mimic_joint_plugin_gazebo name_prefix="left_middle_j2"
    parent_joint="left_middle_j1" mimic_joint="left_middle_j2" multiplier="1.0" offset="0.0" />
	<xacro:mimic_joint_plugin_gazebo name_prefix="left_ring_j2"
    parent_joint="left_ring_j1" mimic_joint="left_ring_j2" multiplier="1.0" offset="0.0" />
  <xacro:mimic_joint_plugin_gazebo name_prefix="left_pinky_j1"
    parent_joint="left_ring_j1" mimic_joint="left_pinky_j1" multiplier="1.0" offset="0.0" />
	<xacro:mimic_joint_plugin_gazebo name_prefix="left_pinky_j2"
    parent_joint="left_ring_j1" mimic_joint="left_pinky_j2" multiplier="1.0" offset="0.0" />



  <link
    name="right_palm_link">
    <inertial>
      <origin
        xyz="-0.0144809215118954 -0.0132347085538364 0.022306335464008"
        rpy="0 0 0" />
      <mass
        value="0.0852752510078387" />
      <inertia
        ixx="0.000154775131402232"
        ixy="1.85109602266807E-05"
        ixz="7.47252049170957E-06"
        iyy="0.000107981762301999"
        iyz="-1.08345230717271E-06"
        izz="0.000125562926987643" />
    </inertial>
    <visual>
      <origin
        xyz="0 0 0"
        rpy="0 0 0" />
      <geometry>
        <mesh
          filename="package://walker_description/meshes/right_palm_link.STL" />
      </geometry>
      <material
        name="">
        <color
          rgba="0.752941176470588 0.752941176470588 0.752941176470588 1" />
      </material>
    </visual>
    <collision>
      <origin
        xyz="-0.020 -0.005 0.020"
        rpy="0 0 0" />
      <geometry>
        <box size="0.040 0.090 0.100"/>
      </geometry>
    </collision>
  </link>
	<gazebo reference="right_palm_link">
    <!-- <selfCollide>true</selfCollide>-->
    <material>Gazebo/White</material>
    <mu1>1000.0</mu1>
    <mu2>1000.0</mu2>
    <fdir1>0.0 0.0 1.0</fdir1>
    <kp>1e5</kp>
    <kd>1.0</kd>
  </gazebo>
	<joint
    name="right_palm_joint"
    type="fixed">
    <origin
      xyz="-0.074796 0.0065547 0.01588"
      rpy="3.14159 -1.947E-07 1.309" /><!--rpy="0 0 1.7826" xyz="0.073849 0.0065547 0.01588-->

    <parent
      link="world" />
    <child
      link="right_palm_link" />
    <axis
      xyz="0 0 0" />
  </joint>
	<gazebo reference="right_palm_joint">
    <implicitSpringDamper>true</implicitSpringDamper>
  </gazebo>
	<link
    name="right_thumb_l1">
    <inertial>
      <origin
        xyz="0.0109078578963968 -0.000509975490591813 -0.00754093105655529"
        rpy="0 0 0" />
      <mass
        value="0.00861449029296223" />
      <inertia
        ixx="6.47380528453408E-07"
        ixy="2.31441793919066E-08"
        ixz="-4.86167105843724E-09"
        iyy="1.90689640236326E-06"
        iyz="-1.39055202752738E-09"
        izz="1.9883580412794E-06" />
    </inertial>
    <visual>
      <origin
        xyz="0 0 0"
        rpy="0 0 0" />
      <geometry>
        <mesh
          filename="package://walker_description/meshes/right_thumb_l1.STL" />
      </geometry>
      <material
        name="">
        <color
          rgba="0.752941176470588 0.752941176470588 0.752941176470588 1" />
      </material>
    </visual>
    <collision>
      <origin
        xyz="0.008 -0.001 -0.008"
        rpy="0 1.5708 0" />
      <geometry>
        <cylinder length="0.028" radius="0.012"/>
      </geometry>
    </collision>
  </link>
	<gazebo reference="right_thumb_l1">
    <!-- <selfCollide>true</selfCollide>-->
  </gazebo>
	<joint
    name="right_thumb_j1"
    type="revolute">
    <origin
      xyz="0.029243 -0.01232 0.046918"
      rpy="0.2841 0.15098 -0.74405" />
    <parent
      link="right_palm_link" />
    <child
      link="right_thumb_l1" />
    <axis
      xyz="0 0 -1" />
    <limit
      lower="0"
      upper="1.5708"
      effort="1.0"
      velocity="10" />
		<dynamics damping="0.01" friction="0.0"/>
  </joint>
	<gazebo reference="right_thumb_j1">
    <implicitSpringDamper>true</implicitSpringDamper>
  </gazebo>
	<link
    name="right_thumb_l2">
    <inertial>
      <origin
        xyz="0.0038139122437023 -0.00519298982364705 0.00691359394439273"
        rpy="0 0 0" />
      <mass
        value="0.00424317818671721" />
      <inertia
        ixx="3.5640013810942E-07"
        ixy="1.05147480910049E-07"
        ixz="8.76003562788286E-10"
        iyy="2.70951305064946E-07"
        iyz="-1.69974504756699E-09"
        izz="4.26072223593812E-07" />
    </inertial>
    <visual>
      <origin
        xyz="0 0 0"
        rpy="0 0 0" />
      <geometry>
        <mesh
          filename="package://walker_description/meshes/right_thumb_l2.STL" />
      </geometry>
      <material
        name="">
        <color
          rgba="0.752941176470588 0.752941176470588 0.752941176470588 1" />
      </material>
    </visual>
    <collision>
      <origin
        xyz="0.007 -0.009 0.007"
        rpy="0 1.5708 -0.7854" />
      <geometry>
        <cylinder length="0.025" radius="0.012"/>
      </geometry>
    </collision>
  </link>
	<gazebo reference="right_thumb_l2">
    <!-- <selfCollide>true</selfCollide>-->
    <material>Gazebo/White</material>
    <mu1>1000.0</mu1>
    <mu2>1000.0</mu2>
    <fdir1>0.0 0.0 1.0</fdir1>
    <kp>1e5</kp>
    <kd>1.0</kd>
  </gazebo>
	<joint
    name="right_thumb_j2"
    type="revolute">
    <origin
      xyz="0.03655 0 -0.014481"
      rpy="-9.1041E-12 5.5133E-12 0.77938" />
    <parent
      link="right_thumb_l1" />
    <child
      link="right_thumb_l2" />
    <axis
      xyz="0 0 -1" />
    <limit
      lower="0"
      upper="1.5708"
      effort="1.0"
      velocity="10" />
		<dynamics damping="0.01" friction="0.0"/>
    <mimic joint="right_thumb_j1" multiplier="1.0" offset="0.0" />
  </joint>
	<gazebo reference="right_thumb_j2">
    <implicitSpringDamper>true</implicitSpringDamper>
  </gazebo>
	<link
    name="right_index_l1">
    <inertial>
      <origin
        xyz="0.0152771482029122 0.000408639325090332 -0.00626307273726445"
        rpy="0 0 0" />
      <mass
        value="0.00605247314202731" />
      <inertia
        ixx="3.65783992375028E-07"
        ixy="-1.00934807957291E-08"
        ixz="2.80428619617228E-09"
        iyy="1.39916151323369E-06"
        iyz="-6.9923785252466E-10"
        izz="1.41553939969596E-06" />
    </inertial>
    <visual>
      <origin
        xyz="0 0 0"
        rpy="0 0 0" />
      <geometry>
        <mesh
          filename="package://walker_description/meshes/right_index_l1.STL" />
      </geometry>
      <material
        name="">
        <color
          rgba="0.752941176470588 0.752941176470588 0.752941176470588 1" />
      </material>
    </visual>
    <collision>
      <origin
        xyz="0.014 0 -0.007"
        rpy="0 1.5708 0" />
      <geometry>
        <cylinder length="0.034" radius="0.010"/>
      </geometry>
    </collision>
  </link>
	<gazebo reference="right_index_l1">
    <!-- <selfCollide>true</selfCollide>-->
  </gazebo>
	<joint
    name="right_index_j1"
    type="revolute">
    <origin
      xyz="-0.017699 -0.07587 0.055574"
      rpy="0.02196 0.053684 -1.3927" />
    <parent
      link="right_palm_link" />
    <child
      link="right_index_l1" />
    <axis
      xyz="0 0 1" />
    <limit
      lower="0"
      upper="1.5708"
      effort="1.0"
      velocity="10" />
		<dynamics damping="0.01" friction="0.0"/>
  </joint>
	<gazebo reference="right_index_j1">
    <implicitSpringDamper>true</implicitSpringDamper>
  </gazebo>
	<link
    name="right_index_l2">
    <inertial>
      <origin
        xyz="0.00234422723007119 -0.0102129867424652 0.00542736940606858"
        rpy="0 0 0" />
      <mass
        value="0.00445698708822686" />
      <inertia
        ixx="5.55945076014283E-07"
        ixy="7.93649952032288E-08"
        ixz="3.91934574204375E-09"
        iyy="2.06935930101655E-07"
        iyz="-2.05205145649726E-08"
        izz="5.96534224716826E-07" />
    </inertial>
    <visual>
      <origin
        xyz="0 0 0"
        rpy="0 0 0" />
      <geometry>
        <mesh
          filename="package://walker_description/meshes/right_index_l2.STL" />
      </geometry>
      <material
        name="">
        <color
          rgba="0.752941176470588 0.752941176470588 0.752941176470588 1" />
      </material>
    </visual>
    <collision>
      <origin
        xyz="0.002 -0.014 0.005"
        rpy="1.5708 0 0.1745" />
      <geometry>
        <cylinder length="0.032" radius="0.010"/>
      </geometry>
    </collision>
  </link>
	<gazebo reference="right_index_l2">
    <!-- <selfCollide>true</selfCollide>-->
    <material>Gazebo/White</material>
    <mu1>1000.0</mu1>
    <mu2>1000.0</mu2>
    <fdir1>0.0 0.0 1.0</fdir1>
    <kp>1e5</kp>
    <kd>1.0</kd>
  </gazebo>
	<joint
    name="right_index_j2"
    type="revolute">
    <origin
      xyz="0.038459 0 -0.012377"
      rpy="-0.056721 0.01211 1.393" />
    <parent
      link="right_index_l1" />
    <child
      link="right_index_l2" />
    <axis
      xyz="-0.01211 -0.056687 0.99832" />
    <limit
      lower="0"
      upper="1.5708"
      effort="1.0"
      velocity="10" />
		<dynamics damping="0.01" friction="0.0"/>
    <mimic joint="right_index_j1" multiplier="1.0" offset="0.0" />
  </joint>
	<gazebo reference="right_index_j2">
    <implicitSpringDamper>true</implicitSpringDamper>
  </gazebo>
	<link
    name="right_middle_l1">
    <inertial>
      <origin
        xyz="0.0152762687335811 0.000409441523501169 -0.00626287883593529"
        rpy="0 0 0" />
      <mass
        value="0.00605245451819771" />
      <inertia
        ixx="3.65760702571658E-07"
        ixy="-1.01893397954424E-08"
        ixz="2.77675028804505E-09"
        iyy="1.39915356053442E-06"
        iyz="-7.67361702883963E-10"
        izz="1.41551554295189E-06" />
    </inertial>
    <visual>
      <origin
        xyz="0 0 0"
        rpy="0 0 0" />
      <geometry>
        <mesh
          filename="package://walker_description/meshes/right_middle_l1.STL" />
      </geometry>
      <material
        name="">
        <color
          rgba="0.752941176470588 0.752941176470588 0.752941176470588 1" />
      </material>
    </visual>
    <collision>
      <origin
        xyz="0.014 0 -0.007"
        rpy="0 1.5708 0" />
      <geometry>
        <cylinder length="0.034" radius="0.010"/>
      </geometry>
    </collision>
  </link>
	<gazebo reference="right_middle_l1">
    <!-- <selfCollide>true</selfCollide>-->
  </gazebo>
	<joint
    name="right_middle_j1"
    type="revolute">
    <origin
      xyz="-0.018928 -0.080828 0.031376"
      rpy="0.025306 0.052053 -1.3281" />
    <parent
      link="right_palm_link" />
    <child
      link="right_middle_l1" />
    <axis
      xyz="0 0 1" />
    <limit
      lower="0"
      upper="1.5708"
      effort="1.0"
      velocity="10" />
		<dynamics damping="0.01" friction="0.0"/>
  </joint>
	<gazebo reference="right_middle_j1">
    <implicitSpringDamper>true</implicitSpringDamper>
  </gazebo>
	<link
    name="right_middle_l2">
    <inertial>
      <origin
        xyz="0.00289048514159018 -0.0100490531988506 0.00544431144992846"
        rpy="0 0 0" />
      <mass
        value="0.00445696556461065" />
      <inertia
        ixx="5.45564758790963E-07"
        ixy="9.81535413955714E-08"
        ixz="4.85238074391545E-09"
        iyy="2.11707171087764E-07"
        iyz="-1.96865301788014E-08"
        izz="5.91025277276737E-07" />
    </inertial>
    <visual>
      <origin
        xyz="0 0 0"
        rpy="0 0 0" />
      <geometry>
        <mesh
          filename="package://walker_description/meshes/right_middle_l2.STL" />
      </geometry>
      <material
        name="">
        <color
          rgba="0.752941176470588 0.752941176470588 0.752941176470588 1" />
      </material>
    </visual>
    <collision>
      <origin
        xyz="0.002 -0.014 0.005"
        rpy="1.5708 0 0.1745" />
      <geometry>
        <cylinder length="0.032" radius="0.010"/>
      </geometry>
    </collision>
  </link>
	<gazebo reference="right_middle_l2">
    <!-- <selfCollide>true</selfCollide>-->
    <material>Gazebo/White</material>
    <mu1>1000.0</mu1>
    <mu2>1000.0</mu2>
    <fdir1>0.0 0.0 1.0</fdir1>
    <kp>1e5</kp>
    <kd>1.0</kd>
  </gazebo>
	<joint
    name="right_middle_j2"
    type="revolute">
    <origin
      xyz="0.038459 0 -0.0122"
      rpy="-0.056603 0.012064 1.3285" />
    <parent
      link="right_middle_l1" />
    <child
      link="right_middle_l2" />
    <axis
      xyz="-0.012065 -0.056562 0.99833" />
    <limit
      lower="0"
      upper="1.5708"
      effort="1.0"
      velocity="10" />
		<dynamics damping="0.01" friction="0.0"/>
    <mimic joint="right_middle_j1" multiplier="1.0" offset="0.0" />
  </joint>
	<gazebo reference="right_middle_j2">
    <implicitSpringDamper>true</implicitSpringDamper>
  </gazebo>
	<link
    name="right_ring_l1">
    <inertial>
      <origin
        xyz="0.0152790983713928 -0.000407929740707025 0.00626138266965892"
        rpy="0 0 0" />
      <mass
        value="0.00605247678962561" />
      <inertia
        ixx="3.65675226655157E-07"
        ixy="1.01164336091825E-08"
        ixz="-2.81242513232345E-09"
        iyy="1.39904698102302E-06"
        iyz="-7.46466225242176E-10"
        izz="1.41555060676411E-06" />
    </inertial>
    <visual>
      <origin
        xyz="0 0 0"
        rpy="0 0 0" />
      <geometry>
        <mesh
          filename="package://walker_description/meshes/right_ring_l1.STL" />
      </geometry>
      <material
        name="">
        <color
          rgba="0.752941176470588 0.752941176470588 0.752941176470588 1" />
      </material>
    </visual>
    <collision>
      <origin
        xyz="0.014 0 0.007"
        rpy="0 1.5708 0" />
      <geometry>
        <cylinder length="0.034" radius="0.010"/>
      </geometry>
    </collision>
  </link>
	<gazebo reference="right_ring_l1">
    <!-- <selfCollide>true</selfCollide>-->
  </gazebo>
	<joint
    name="right_ring_j1"
    type="revolute">
    <origin
      xyz="-0.017845 -0.074821 0.007677"
      rpy="-3.1203 0.05396 -1.4056" />
    <parent
      link="right_palm_link" />
    <child
      link="right_ring_l1" />
    <axis
      xyz="1.7588E-05 0 -1" />
    <limit
      lower="0"
      upper="1.5708"
      effort="1.0"
      velocity="10" />
		<dynamics damping="0.01" friction="0.0"/>
  </joint>
	<gazebo reference="right_ring_j1">
    <implicitSpringDamper>true</implicitSpringDamper>
  </gazebo>
	<link
    name="right_ring_l2">
    <inertial>
      <origin
        xyz="0.00226446203390765 -0.0102341141638748 0.00542585656729089"
        rpy="0 0 0" />
      <mass
        value="0.00445699860314573" />
      <inertia
        ixx="5.57270584510554E-07"
        ixy="7.65166590723597E-08"
        ixz="3.78737544474429E-09"
        iyy="2.05690510460265E-07"
        iyz="-2.06747876235999E-08"
        izz="5.96524268555039E-07" />
    </inertial>
    <visual>
      <origin
        xyz="0 0 0"
        rpy="0 0 0" />
      <geometry>
        <mesh
          filename="package://walker_description/meshes/right_ring_l2.STL" />
      </geometry>
      <material
        name="">
        <color
          rgba="0.752941176470588 0.752941176470588 0.752941176470588 1" />
      </material>
    </visual>
    <collision>
      <origin
        xyz="0.002 -0.014 0.005"
        rpy="1.5708 0 0.1745" />
      <geometry>
        <cylinder length="0.032" radius="0.010"/>
      </geometry>
    </collision>
  </link>
	<gazebo reference="right_ring_l2">
    <!-- <selfCollide>true</selfCollide>-->
    <material>Gazebo/White</material>
    <mu1>1000.0</mu1>
    <mu2>1000.0</mu2>
    <fdir1>0.0 0.0 1.0</fdir1>
    <kp>1e5</kp>
    <kd>1.0</kd>
  </gazebo>
	<joint
    name="right_ring_j2"
    type="revolute">
    <origin
      xyz="0.038461 0 0.012203"
      rpy="3.0849 -0.012117 -1.4058" />
    <parent
      link="right_ring_l1" />
    <child
      link="right_ring_l2" />
    <axis
      xyz="-0.012113 -0.056705 0.99832" />
    <limit
      lower="0"
      upper="1.5708"
      effort="1.0"
      velocity="10" />
		<dynamics damping="0.01" friction="0.0"/>
    <mimic joint="right_ring_j1" multiplier="1.0" offset="0.0" />
  </joint>
	<gazebo reference="right_ring_j2">
    <implicitSpringDamper>true</implicitSpringDamper>
  </gazebo>
	<link
    name="right_pinky_l1">
    <inertial>
      <origin
        xyz="0.0136417719935673 -0.000125531934202894 -0.00569767013320738"
        rpy="0 0 0" />
      <mass
        value="0.00475338387931075" />
      <inertia
        ixx="2.41836333046606E-07"
        ixy="-7.21453266409586E-09"
        ixz="2.18288517443966E-09"
        iyy="8.45647103827569E-07"
        iyz="-5.90210689072676E-10"
        izz="8.54135009354068E-07" />
    </inertial>
    <visual>
      <origin
        xyz="0 0 0"
        rpy="0 0 0" />
      <geometry>
        <mesh
          filename="package://walker_description/meshes/right_pinky_l1.STL" />
      </geometry>
      <material
        name="">
        <color
          rgba="0.752941176470588 0.752941176470588 0.752941176470588 1" />
      </material>
    </visual>
    <collision>
      <origin
        xyz="0.014 0 -0.007"
        rpy="0 1.5708 0" />
      <geometry>
        <cylinder length="0.034" radius="0.010"/>
      </geometry>
    </collision>
  </link>
	<gazebo reference="right_pinky_l1">
    <!-- <selfCollide>true</selfCollide>-->
  </gazebo>
	<joint
    name="right_pinky_j1"
    type="revolute">
    <origin
      xyz="-0.018167 -0.069717 -0.015649"
      rpy="0.063832 0.04715 -1.3412" />
    <parent
      link="right_palm_link" />
    <child
      link="right_pinky_l1" />
    <axis
      xyz="5.8842E-05 0 1" />
    <limit
      lower="0"
      upper="1.5708"
      effort="1.0"
      velocity="10" />
		<dynamics damping="0.01" friction="0.0"/>
    <mimic joint="right_ring_j1" multiplier="1.0" offset="0.0" />
  </joint>
	<gazebo reference="right_pinky_j1">
    <implicitSpringDamper>true</implicitSpringDamper>
  </gazebo>
	<link
    name="right_pinky_l2">
    <inertial>
      <origin
        xyz="0.00385750559999914 -0.0117317540747605 0.00513394348644691"
        rpy="0 0 0" />
      <mass
        value="0.00390662275645989" />
      <inertia
        ixx="4.90879392525086E-07"
        ixy="1.11650195510708E-07"
        ixz="-8.41646328987664E-10"
        iyy="1.76444115028913E-07"
        iyz="1.94024217356653E-09"
        izz="5.41362797182644E-07" />
    </inertial>
    <visual>
      <origin
        xyz="0 0 0"
        rpy="0 0 0" />
      <geometry>
        <mesh
          filename="package://walker_description/meshes/right_pinky_l2.STL" />
      </geometry>
      <material
        name="">
        <color
          rgba="0.752941176470588 0.752941176470588 0.752941176470588 1" />
      </material>
    </visual>
    <collision>
      <origin
        xyz="0.002 -0.018 0.004"
        rpy="1.5708 0 0.1745" />
      <geometry>
        <cylinder length="0.032" radius="0.010"/>
      </geometry>
    </collision>
  </link>
	<gazebo reference="right_pinky_l2">
    <!-- <selfCollide>true</selfCollide>-->
    <material>Gazebo/White</material>
    <mu1>1000.0</mu1> 
    <mu2>1000.0</mu2>
    <fdir1>0.0 0.0 1.0</fdir1>
    <kp>1e5</kp>
    <kd>1.0</kd>
  </gazebo>
	<joint
    name="right_pinky_j2"
    type="revolute">
    <origin
      xyz="0.033786 -0.00038214 -0.010543"
      rpy="7.2607E-05 6.2497E-06 1.3443" />
    <parent
      link="right_pinky_l1" />
    <child
      link="right_pinky_l2" />
    <axis
      xyz="0 0 1" />
    <limit
      lower="0"
      upper="1.5708"
      effort="1.0"
      velocity="10" />
		<dynamics damping="0.01" friction="0.0"/>
    <mimic joint="right_ring_j1" multiplier="1.0" offset="0.0" />
  </joint>
	<gazebo reference="right_pinky_j2">
    <implicitSpringDamper>true</implicitSpringDamper>
  </gazebo>

	<xacro:mimic_joint_plugin_gazebo name_prefix="right_thumb_j2"
    parent_joint="right_thumb_j1" mimic_joint="right_thumb_j2" multiplier="1.0" offset="0.0" />
	<xacro:mimic_joint_plugin_gazebo name_prefix="right_index_j2"
    parent_joint="right_index_j1" mimic_joint="right_index_j2" multiplier="1.0" offset="0.0" />
  <xacro:mimic_joint_plugin_gazebo name_prefix="right_middle_j2"
    parent_joint="right_middle_j1" mimic_joint="right_middle_j2" multiplier="1.0" offset="0.0" />
  <xacro:mimic_joint_plugin_gazebo name_prefix="right_ring_j2"
    parent_joint="right_ring_j1" mimic_joint="right_ring_j2" multiplier="1.0" offset="0.0" />
  <xacro:mimic_joint_plugin_gazebo name_prefix="right_pinky_j1"
    parent_joint="right_ring_j1" mimic_joint="right_pinky_j1" multiplier="1.0" offset="0.0" />
  <xacro:mimic_joint_plugin_gazebo name_prefix="right_pinky_j2"
    parent_joint="right_ring_j1" mimic_joint="right_pinky_j2" multiplier="1.0" offset="0.0" />

</robot>
